<mujoco model="go1_wx250s">
  <compiler angle="radian" meshdir="assets" texturedir="assets" autolimits="true"/>

  <option cone="elliptic" impratio="100"/>

  <default>

     <!-- wx250S -->
    <default class="wx250s">
        <mesh scale="0.001 0.001 0.001"/>
        <joint axis="0 1 0" frictionloss="0.1" armature="0.1" damping="10"/>
        <default class="wx250s_visual">
            <geom type="mesh" contype="0" conaffinity="0" density="0" group="2" material="black"/>
        </default>
        <default class="wx250s_collision">
            <geom group="3" type="mesh"/>
            <default class="sphere_collision">
            <geom type="sphere" size="0.0006" rgba="1 0 0 1"/>
            </default>
        </default>
    </default>

    <!-- GO1 -->
    <default class="go1">
      <geom friction="0.6" margin="0.001" condim="1"/>
      <joint axis="0 1 0" damping="2" armature="0.01" frictionloss="0.2"/>
     
      <default class="abduction">
        <joint axis="1 0 0" damping="1" range="-0.863 0.863"/>
        
      </default>
      <default class="hip">
        <joint range="-0.686 4.501"/>
        
      </default>
      <default class="knee">
        <joint range="-2.818 -0.888"/>
       
      </default>
      <default class="go1_visual">
        <geom type="mesh" contype="0" conaffinity="0" group="2" material="dark"/>
      </default>
      <default class="go1_collision">
        <geom group="3" type="capsule"/>
        <default class="hip_left1">
          <geom size="0.046 0.02" pos="0 0.045 0" quat="1 1 0 0" type="cylinder"/>
        </default>
        <default class="hip_left2">
          <geom size="0.031 0.02" pos="0 0.065 0" quat="1 1 0 0" type="cylinder"/>
        </default>
        <default class="hip_left3">
          <geom size="0.046 0.02" quat="1 1 0 0" type="cylinder"/>
        </default>
        <default class="hip_right1">
          <geom size="0.046 0.02" pos="0 -0.045 0" quat="1 1 0 0" type="cylinder"/>
        </default>
        <default class="hip_right2">
          <geom size="0.031 0.02" pos="0 -0.065 0" quat="1 1 0 0" type="cylinder"/>
        </default>
        <default class="hip_right3">
          <geom size="0.046 0.02" quat="1 1 0 0" type="cylinder"/>
        </default>
        <default class="thigh1">
          <geom size="0.015" fromto="-0.02 0 0 -0.02 0 -0.16"/>
        </default>
        <default class="thigh2">
          <geom size="0.015" fromto="0 0 0 -0.02 0 -0.1"/>
        </default>
        <default class="thigh3">
          <geom size="0.015" fromto="-0.02 0 -0.16 0 0 -0.2"/>
        </default>
        <default class="calf1">
          <geom size="0.01" fromto="0 0 0 0.02 0 -0.13"/>
        </default>
        <default class="calf2">
          <geom size="0.01" fromto="0.02 0 -0.13 0 0 -0.2"/>
        </default>
        <default class="foot">
          <geom type="sphere" size="0.023" pos="0 0 -0.213" priority="1" solimp="0.015 1 0.023" condim="6"
            friction="0.8 0.02 0.01"/>
        </default>
      </default>
    </default>
  </default>

  <asset>
    <texture name="grid" type="2d" builtin="checker" width="512" height="512" rgb1=".1 .2 .3" rgb2=".2 .3 .4"/>
    <material name="grid" texture="grid" texrepeat="1 1" texuniform="true" reflectance=".2"/>

    <!-- GO1 -->
    <material name="dark" rgba="0.2 0.2 0.2 1"/>
    <mesh class="go1" file="trunk.stl"/>
    <mesh class="go1" file="hip.stl"/>
    <mesh class="go1" file="thigh_mirror.stl"/>
    <mesh class="go1" file="calf.stl"/>
    <mesh class="go1" file="thigh.stl"/>

    <!-- wx250S -->
    <texture type="2d" file="interbotix_black.png"/>
    <material name="black" texture="interbotix_black"/>

    <mesh file="wx250s_1_base.stl" class="wx250s"/>
    <mesh file="wx250s_2_shoulder.stl" class="wx250s"/>
    <mesh file="wx250s_3_upper_arm.stl" class="wx250s"/>
    <mesh file="wx250s_4_upper_forearm.stl" class="wx250s"/>
    <mesh file="wx250s_5_lower_forearm.stl" class="wx250s"/>
    <mesh file="wx250s_6_wrist.stl" class="wx250s"/>
    <mesh file="wx250s_7_gripper.stl" class="wx250s"/>
    <mesh file="wx250s_8_gripper_prop.stl" class="wx250s"/>
    <mesh file="wx250s_9_gripper_bar.stl" class="wx250s"/>
    <mesh file="wx250s_10_gripper_finger.stl" class="wx250s"/>

  </asset>

  <worldbody>
    <light name="spotlight" mode="targetbodycom" target="trunk" pos="0 -1 2"/>
    <geom name="floor" size="0 0 .05" type="plane" material="grid" condim="3"/>
    <!-- GO1 -->
    <body name="trunk" pos="0 0 .43" childclass="go1">
      <camera name="tracking" mode="trackcom" pos="0 -1 0.8" xyaxes="1 0 0 0 1 1"/>
      <site name="head" pos="0.3 0 0" rgba="1 0 0 1" size="0.02" group="5"/>
      <inertial pos="0.0223 0.002 -0.0005" quat="-0.00342088 0.705204 0.000106698 0.708996" mass="5.204"
        diaginertia="0.0716565 0.0630105 0.0168101"/>
      <freejoint/>
      <geom class="go1_visual" mesh="trunk"/>
      <geom class="go1_collision" size="0.125 0.04 0.057" type="box"/>
      <geom class="go1_collision" quat="1 0 1 0" pos="0 -0.04 0" size="0.058 0.125" type="cylinder"/>
      <geom class="go1_collision" quat="1 0 1 0" pos="0 +0.04 0" size="0.058 0.125" type="cylinder"/>
      <geom class="go1_collision" pos="0.25 0 0" size="0.005 0.06 0.05" type="box"/>
      <geom class="go1_collision" pos="0.25 0.06 -0.01" size="0.009 0.035"/>
      <geom class="go1_collision" pos="0.25 -0.06 -0.01" size="0.009 0.035"/>
      <geom class="go1_collision" pos="0.25 0 -0.05" size="0.01 0.06" quat="1 1 0 0"/>
      <geom class="go1_collision" pos="0.255 0 0.0355" size="0.021 0.052" quat="1 1 0 0"/>
      <site name="imu" pos="0 0 0"/>
      
      <body name="FL_hip" pos="0.1881 0.04675 0">
        <inertial pos="-0.0049166 -0.00762615 -8.865e-05" quat="0.482891 0.495027 0.514169 0.507341" mass="0.68"
          diaginertia="0.000734064 0.000468438 0.000398719"/>
        <joint class="abduction" name="FL_hip_joint"/>
        <geom class="go1_visual" mesh="hip"/>
        <geom class="hip_left1"/>
        <geom class="hip_left2"/>
        <body name="FL_thigh" pos="0 0.08 0">
          <inertial pos="-0.00304722 -0.019315 -0.0305004" quat="0.753383 0.0775126 -0.0272313 0.65243" mass="1.009"
            diaginertia="0.00478717 0.00460903 0.000709268"/>
          <joint class="hip" name="FL_thigh_joint"/>
          <geom class="go1_visual" mesh="thigh"/>
          <geom class="thigh1"/>
          <geom class="thigh2"/>
          <geom class="thigh3"/>
          <body name="FL_calf" pos="0 0 -0.213">
            <inertial pos="0.00429862 0.000976676 -0.146197" quat="0.691246 0.00357467 0.00511118 0.722592"
              mass="0.195862" diaginertia="0.00149767 0.00148468 3.58427e-05"/>
            <joint class="knee" name="FL_calf_joint"/>
            <geom class="go1_visual" mesh="calf"/>
            <geom class="calf1"/>
            <geom class="calf2"/>
            <geom name="FL" class="foot"/>
            <site name="FL" pos="0 0 -0.213" type="sphere" size="0.023" group="5"/>
          </body>
        </body>
      </body>
      
      <body name="FR_hip" pos="0.1881 -0.04675 0">
        <inertial pos="-0.0049166 0.00762615 -8.865e-05" quat="0.507341 0.514169 0.495027 0.482891" mass="0.68"
          diaginertia="0.000734064 0.000468438 0.000398719"/>
        <joint class="abduction" name="FR_hip_joint"/>
        <geom class="go1_visual" mesh="hip" quat="1 0 0 0"/>
        <geom class="hip_right1"/>
        <geom class="hip_right2"/>
        <body name="FR_thigh" pos="0 -0.08 0">
          <inertial pos="-0.00304722 0.019315 -0.0305004" quat="0.65243 -0.0272313 0.0775126 0.753383" mass="1.009"
            diaginertia="0.00478717 0.00460903 0.000709268"/>
          <joint class="hip" name="FR_thigh_joint"/>
          <geom class="go1_visual" mesh="thigh_mirror"/>
          <geom class="thigh1"/>
          <geom class="thigh2"/>
          <geom class="thigh3"/>
          <body name="FR_calf" pos="0 0 -0.213">
            <inertial pos="0.00429862 0.000976676 -0.146197" quat="0.691246 0.00357467 0.00511118 0.722592"
              mass="0.195862" diaginertia="0.00149767 0.00148468 3.58427e-05"/>
            <joint class="knee" name="FR_calf_joint"/>
            <geom class="go1_visual" mesh="calf"/>
            <geom class="calf1"/>
            <geom class="calf2"/>
            <geom name="FR" class="foot"/>
            <site name="FR" pos="0 0 -0.213" type="sphere" size="0.023" group="5"/>
          </body>
        </body>
      </body>
      
      
      <body name="RL_hip" pos="-0.1881 0.04675 0">
        <inertial pos="0.0049166 -0.00762615 -8.865e-05" quat="0.514169 0.507341 0.482891 0.495027" mass="0.68"
          diaginertia="0.000734064 0.000468438 0.000398719"/>
        <joint class="abduction" name="RL_hip_joint"/>
        <geom class="go1_visual" quat="0 0 1 0" mesh="hip"/>
        <geom class="hip_left1"/>
        <geom class="hip_left2"/>
        <geom class="hip_left3"/>
        <body name="RL_thigh" pos="0 0.08 0">
          <inertial pos="-0.00304722 -0.019315 -0.0305004" quat="0.753383 0.0775126 -0.0272313 0.65243" mass="1.009"
            diaginertia="0.00478717 0.00460903 0.000709268"/>
          <joint class="hip" name="RL_thigh_joint"/>
          <geom class="go1_visual" mesh="thigh"/>
          <geom class="thigh1"/>
          <geom class="thigh2"/>
          <geom class="thigh3"/>
          <body name="RL_calf" pos="0 0 -0.213">
            <inertial pos="0.00429862 0.000976676 -0.146197" quat="0.691246 0.00357467 0.00511118 0.722592"
              mass="0.195862" diaginertia="0.00149767 0.00148468 3.58427e-05"/>
            <joint class="knee" name="RL_calf_joint"/>
            <geom class="go1_visual" mesh="calf"/>
            <geom class="calf1"/>
            <geom class="calf2"/>
            <geom name="RL" class="foot"/>
            <site name="RL" pos="0 0 -0.213" type="sphere" size="0.023" group="5"/>
          </body>
        </body>
      </body>

      <body name="RR_hip" pos="-0.1881 -0.04675 0">
        <inertial pos="0.0049166 0.00762615 -8.865e-05" quat="0.495027 0.482891 0.507341 0.514169" mass="0.68"
          diaginertia="0.000734064 0.000468438 0.000398719"/>
        <joint class="abduction" name="RR_hip_joint"/>
        <geom class="go1_visual" quat="0 0 0 -1" mesh="hip"/>
        <geom class="hip_right1"/>
        <geom class="hip_right2"/>
        <geom class="hip_right3"/>
        <body name="RR_thigh" pos="0 -0.08 0">
          <inertial pos="-0.00304722 0.019315 -0.0305004" quat="0.65243 -0.0272313 0.0775126 0.753383" mass="1.009"
            diaginertia="0.00478717 0.00460903 0.000709268"/>
          <joint class="hip" name="RR_thigh_joint"/>
          <geom class="go1_visual" mesh="thigh_mirror"/>
          <geom class="thigh1"/>
          <geom class="thigh2"/>
          <geom class="thigh3"/>
          <body name="RR_calf" pos="0 0 -0.213">
            <inertial pos="0.00429862 0.000976676 -0.146197" quat="0.691246 0.00357467 0.00511118 0.722592"
              mass="0.195862" diaginertia="0.00149767 0.00148468 3.58427e-05"/>
            <joint class="knee" name="RR_calf_joint"/>
            <geom class="go1_visual" mesh="calf"/>
            <geom class="calf1"/>
            <geom class="calf2"/>
            <geom name="RR" class="foot"/>
            <site name="RR" pos="0 0 -0.213" type="sphere" size="0.023" group="5"/>
          </body>
        </body>
      </body>

      <!-- wx250S -->
      <body name="wx250s/base_link" childclass="wx250s" pos="0 0 .058">
        <inertial pos="-0.0380446 0.000613892 0.0193354" quat="0.509292 0.490887 -0.496359 0.503269" mass="0.538736"
          diaginertia="0.00252518 0.00211519 0.000690737"/>
        <geom quat="1 0 0 1" mesh="wx250s_1_base" class="wx250s_visual"/>
        <geom quat="1 0 0 1" mesh="wx250s_1_base" class="wx250s_collision"/>
        <body name="wx250s/shoulder_link" pos="0 0 0.072">
          <inertial pos="2.23482e-05 4.14609e-05 0.0066287" quat="0.0130352 0.706387 0.012996 0.707586" mass="0.480879"
            diaginertia="0.000588946 0.000555655 0.000378999"/>
          <joint name="waist" axis="0 0 1" range="-3.14158 3.14158"/>
          <geom pos="0 0 -0.003" quat="1 0 0 1" mesh="wx250s_2_shoulder" class="wx250s_visual"/>
          <geom pos="0 0 -0.003" quat="1 0 0 1" mesh="wx250s_2_shoulder" class="wx250s_collision"/>
          <body name="wx250s/upper_arm_link" pos="0 0 0.03865">
            <inertial pos="0.0171605 2.725e-07 0.191323" quat="0.705539 0.0470667 -0.0470667 0.705539" mass="0.430811"
              diaginertia="0.00364425 0.003463 0.000399348"/>
            <joint name="shoulder" range="-1.88496 1.98968"/>
            <geom quat="1 0 0 1" mesh="wx250s_3_upper_arm" class="wx250s_visual"/>
            <geom quat="1 0 0 1" mesh="wx250s_3_upper_arm" class="wx250s_collision"/>
            <body name="wx250s/upper_forearm_link" pos="0.04975 0 0.25">
              <inertial pos="0.107963 0.000115876 0" quat="0.000980829 0.707106 -0.000980829 0.707106" mass="0.234589"
                diaginertia="0.000888 0.000887807 3.97035e-05"/>
              <joint name="elbow" range="-2.14675 1.6057"/>
              <geom mesh="wx250s_4_upper_forearm" class="wx250s_visual"/>
              <geom mesh="wx250s_4_upper_forearm" class="wx250s_collision"/>
              <body name="wx250s/lower_forearm_link" pos="0.175 0 0">
                <inertial pos="0.0374395 0.00522252 0" quat="-0.0732511 0.703302 0.0732511 0.703302" mass="0.220991"
                  diaginertia="0.0001834 0.000172527 5.88633e-05"/>
                <joint name="forearm_roll" axis="1 0 0" range="-3.14158 3.14158"/>
                <geom quat="0 1 0 0" mesh="wx250s_5_lower_forearm" class="wx250s_visual"/>
                <geom quat="0 1 0 0" mesh="wx250s_5_lower_forearm" class="wx250s_collision"/>
                <body name="wx250s/wrist_link" pos="0.075 0 0">
                  <inertial pos="0.04236 -1.0663e-05 0.010577" quat="0.608721 0.363497 -0.359175 0.606895" mass="0.084957"
                    diaginertia="3.29057e-05 3.082e-05 2.68343e-05"/>
                  <joint name="wrist_angle" axis="0 1 0" range="-1.74533 2.14675"/>
                  <geom quat="1 0 0 1" mesh="wx250s_6_wrist" class="wx250s_visual"/>
                  <geom quat="1 0 0 1" mesh="wx250s_6_wrist" class="wx250s_collision"/>
                  <body name="wx250s/gripper_link" pos="0.065 0 0">
                    <inertial pos="0.0325296 4.2061e-07 0.0090959" quat="0.546081 0.419626 0.62801 0.362371"
                      mass="0.110084" diaginertia="0.00307592 0.00307326 0.0030332"/>
                    <joint name="wrist_rotate" axis="1 0 0" range="-3.14158 3.14158"/>
                    <geom pos="-0.02 0 0" quat="1 0 0 1" mesh="wx250s_7_gripper" class="wx250s_visual"/>
                    <geom pos="-0.02 0 0" quat="1 0 0 1" mesh="wx250s_7_gripper" class="wx250s_collision"/>
                    <geom pos="-0.02 0 0" quat="1 0 0 1" mesh="wx250s_9_gripper_bar" class="wx250s_visual"/>
                    <geom pos="-0.02 0 0" quat="1 0 0 1" mesh="wx250s_9_gripper_bar" class="wx250s_collision"/>
                    <body name="wx250s/left_finger_link" pos="0.066 0 0">
                      <inertial pos="0.013816 0 0" quat="0.705384 0.705384 -0.0493271 -0.0493271" mass="0.016246"
                        diaginertia="4.79509e-06 3.7467e-06 1.48651e-06"/>
                      <joint name="left_finger" axis="0 1 0" type="slide" range="0.015 0.037"/>
                      <geom pos="0 0.005 0" quat="0 0 0 -1" mesh="wx250s_10_gripper_finger" class="wx250s_visual"/>
                      <geom pos="0 0.005 0" quat="0 0 0 -1" mesh="wx250s_10_gripper_finger" class="wx250s_collision"/>
                      <geom name="left/left_g0" pos="0.042 -0.009 0.012" class="sphere_collision"/>
                      <geom name="left/left_g1" pos="0.042 -0.009 -0.012" class="sphere_collision"/>
                    </body>
                    <body name="wx250s/right_finger_link" pos="0.066 0 0">
                      <inertial pos="0.013816 0 0" quat="0.705384 0.705384 0.0493271 0.0493271" mass="0.016246"
                        diaginertia="4.79509e-06 3.7467e-06 1.48651e-06"/>
                      <joint name="right_finger" axis="0 1 0" type="slide" range="-0.037 -0.015"/>
                      <geom pos="0 -0.005 0" quat="0 0 1 0" mesh="wx250s_10_gripper_finger" class="wx250s_visual"/>
                      <geom pos="0 -0.005 0" quat="0 0 1 0" mesh="wx250s_10_gripper_finger" class="wx250s_collision"/>
                      <geom name="right/right_g0" pos="0.042 0.009 0.012" class="sphere_collision"/>
                      <geom name="right/right_g1" pos="0.042 0.009 -0.012" class="sphere_collision"/>
                    </body>
                  </body>
                </body>
              </body>
            </body>
          </body>
        </body>
      </body>        
    </body>
  </worldbody>

<!-- wx250S -->
  <contact>
    <exclude body1="wx250s/base_link" body2="wx250s/shoulder_link"/>
  </contact>
<!-- wx250S -->
  <equality>
    <joint joint1="left_finger" joint2="right_finger" polycoef="0 -1 0 0 0"/>
  </equality>

  <actuator>
    <!-- go1 -->
    
    <motor class="abduction" name="FL_hip" joint="FL_hip_joint"/>
    <motor class="hip" name="FL_thigh" joint="FL_thigh_joint"/>
    <motor class="knee" name="FL_calf" joint="FL_calf_joint"/>
    <motor class="abduction" name="FR_hip" joint="FR_hip_joint"/>
    <motor class="hip" name="FR_thigh" joint="FR_thigh_joint"/>
    <motor class="knee" name="FR_calf" joint="FR_calf_joint"/>
    
    <motor class="abduction" name="RL_hip" joint="RL_hip_joint"/>
    <motor class="hip" name="RL_thigh" joint="RL_thigh_joint"/>
    <motor class="knee" name="RL_calf" joint="RL_calf_joint"/>
    <motor class="abduction" name="RR_hip" joint="RR_hip_joint"/>
    <motor class="hip" name="RR_thigh" joint="RR_thigh_joint"/>
    <motor class="knee" name="RR_calf" joint="RR_calf_joint"/>

    <!-- wx250S -->
    <motor class="wx250s" name="waist" joint="waist"/>
    <motor class="wx250s" name="shoulder" joint="shoulder"/>
    <motor class="wx250s" name="elbow" joint="elbow"/>
    <motor class="wx250s" name="forearm_roll" joint="forearm_roll"/>
    <motor class="wx250s" name="wrist_angle" joint="wrist_angle"/>
    <motor class="wx250s" name="wrist_rotate" joint="wrist_rotate"/>
    <position class="wx250s" name="gripper" joint="left_finger"/>
  </actuator>

  <keyframe>
  <!-- go1 and  wx250S -->
    <key name="go1_home" qpos="0 0 0.27 1 0 0 0 0 0.9 -1.8 0 0.9 -1.8 0 0.9 -1.8 0 0.9 -1.8 0 -0.96 1.16 0 -0.3 0 0.015 -0.015"
      ctrl="0 0.9 -1.8 0 0.9 -1.8 0 0.9 -1.8 0 0.9 0 0 -0.96 1.16 0 -0.3 0 0.015"/>

    <!-- wx250S 
    <key name="wx250s_home" qpos="0 -0.96 1.16 0 -0.3 0 0.015 -0.015" ctrl="0 -0.96 1.16 0 -0.3 0 0.015"/>
    -->
  </keyframe>
</mujoco>